01/10/2023 08:22:46 PM [CRITICAL] test: merging the 12 ['as', 'bn', 'en', 'gu', 'hi', 'kn', 'ml', 'mr', 'or', 'pa', 'ta', 'te'] different languages dataset
{'test.jsonl'} files are missing, creating the files..
/home/bhavyajeet.singh/anaconda3/envs/xalign/lib/python3.7/site-packages/pytorch_lightning/utilities/distributed.py:45: UserWarning: The dataloader, test dataloader 0, does not have many workers which may be a bottleneck. Consider increasing the value of the `num_workers` argument` (try 40 which is the number of cpus on this machine) in the `DataLoader` init to improve performance.
  warnings.warn(*args, **kwargs)
01/10/2023 08:22:51 PM [CRITICAL] test : script unification to Devanagari is enabled.
01/10/2023 08:22:51 PM [INFO] test dataset count : 12546
Testing: 0it [00:00, ?it/s]
Traceback (most recent call last):
  File "/home/bhavyajeet.singh/msme/MEMS-XF2T/generation/mT5-baseline/main.py", line 615, in <module>
    start_training(args)
  File "/home/bhavyajeet.singh/msme/MEMS-XF2T/generation/mT5-baseline/main.py", line 461, in start_training
    trainer.test(model=model, ckpt_path=checkpoint_file)
  File "/home/bhavyajeet.singh/anaconda3/envs/xalign/lib/python3.7/site-packages/pytorch_lightning/trainer/trainer.py", line 719, in test
    results = self.__test_given_model(model, test_dataloaders)
  File "/home/bhavyajeet.singh/anaconda3/envs/xalign/lib/python3.7/site-packages/pytorch_lightning/trainer/trainer.py", line 784, in __test_given_model
    results = self.fit(model)
  File "/home/bhavyajeet.singh/anaconda3/envs/xalign/lib/python3.7/site-packages/pytorch_lightning/trainer/trainer.py", line 445, in fit
    results = self.accelerator_backend.train()
  File "/home/bhavyajeet.singh/anaconda3/envs/xalign/lib/python3.7/site-packages/pytorch_lightning/accelerators/ddp_accelerator.py", line 148, in train
    results = self.ddp_train(process_idx=self.task_idx, model=model)
  File "/home/bhavyajeet.singh/anaconda3/envs/xalign/lib/python3.7/site-packages/pytorch_lightning/accelerators/ddp_accelerator.py", line 282, in ddp_train
    results = self.train_or_test()
  File "/home/bhavyajeet.singh/anaconda3/envs/xalign/lib/python3.7/site-packages/pytorch_lightning/accelerators/accelerator.py", line 64, in train_or_test
    results = self.trainer.run_test()
  File "/home/bhavyajeet.singh/anaconda3/envs/xalign/lib/python3.7/site-packages/pytorch_lightning/trainer/trainer.py", line 628, in run_test
    eval_loop_results, _ = self.run_evaluation(test_mode=True)
  File "/home/bhavyajeet.singh/anaconda3/envs/xalign/lib/python3.7/site-packages/pytorch_lightning/trainer/trainer.py", line 567, in run_evaluation
    for batch_idx, batch in enumerate(dataloader):
  File "/home/bhavyajeet.singh/anaconda3/envs/xalign/lib/python3.7/site-packages/torch/utils/data/dataloader.py", line 435, in __next__
    data = self._next_data()
  File "/home/bhavyajeet.singh/anaconda3/envs/xalign/lib/python3.7/site-packages/torch/utils/data/dataloader.py", line 1085, in _next_data
    return self._process_data(data)
  File "/home/bhavyajeet.singh/anaconda3/envs/xalign/lib/python3.7/site-packages/torch/utils/data/dataloader.py", line 1111, in _process_data
    data.reraise()
  File "/home/bhavyajeet.singh/anaconda3/envs/xalign/lib/python3.7/site-packages/torch/_utils.py", line 428, in reraise
    raise self.exc_type(msg)
AttributeError: Caught AttributeError in DataLoader worker process 0.
Original Traceback (most recent call last):
  File "/home/bhavyajeet.singh/anaconda3/envs/xalign/lib/python3.7/site-packages/torch/utils/data/_utils/worker.py", line 198, in _worker_loop
    data = fetcher.fetch(index)
  File "/home/bhavyajeet.singh/anaconda3/envs/xalign/lib/python3.7/site-packages/torch/utils/data/_utils/fetch.py", line 44, in fetch
    data = [self.dataset[idx] for idx in possibly_batched_index]
  File "/home/bhavyajeet.singh/anaconda3/envs/xalign/lib/python3.7/site-packages/torch/utils/data/_utils/fetch.py", line 44, in <listcomp>
    data = [self.dataset[idx] for idx in possibly_batched_index]
  File "/home/bhavyajeet.singh/msme/MEMS-XF2T/generation/mT5-baseline/dataloader.py", line 115, in __getitem__
    tgt_ids, tgt_mask = self.preprocess(self.process_text(data_instance['sentence'], lang_iso), self.tgt_max_seq_len)
  File "/home/bhavyajeet.singh/msme/MEMS-XF2T/generation/mT5-baseline/dataloader.py", line 50, in process_text
    return get_text_in_unified_script(text, self.lang_normalizer[lang], lang)
  File "/home/bhavyajeet.singh/msme/MEMS-XF2T/generation/mT5-baseline/utils.py", line 131, in get_text_in_unified_script
    normalizer.normalize(text.strip()), lang
AttributeError: 'list' object has no attribute 'strip'