09/14/2022 03:05:26 AM [CRITICAL] val: merging the 2 ['en', 'hi'] different languages dataset
{'val.jsonl'} files are missing, creating the files..
  | Name  | Type                        | Params
------------------------------------------------------
0 | model | MT5ForConditionalGeneration | 300 M
Traceback (most recent call last):
  File "/home/bhavyajeet.singh/XAlign/src/data-to-text-generator/mT5-baseline/main.py", line 575, in <module>
    start_training(args)
  File "/home/bhavyajeet.singh/XAlign/src/data-to-text-generator/mT5-baseline/main.py", line 426, in start_training
    trainer.fit(model)
  File "/home/bhavyajeet.singh/anaconda3/envs/xalign/lib/python3.7/site-packages/pytorch_lightning/trainer/trainer.py", line 445, in fit
    results = self.accelerator_backend.train()
  File "/home/bhavyajeet.singh/anaconda3/envs/xalign/lib/python3.7/site-packages/pytorch_lightning/accelerators/ddp_accelerator.py", line 148, in train
    results = self.ddp_train(process_idx=self.task_idx, model=model)
  File "/home/bhavyajeet.singh/anaconda3/envs/xalign/lib/python3.7/site-packages/pytorch_lightning/accelerators/ddp_accelerator.py", line 282, in ddp_train
    results = self.train_or_test()
  File "/home/bhavyajeet.singh/anaconda3/envs/xalign/lib/python3.7/site-packages/pytorch_lightning/accelerators/accelerator.py", line 66, in train_or_test
    results = self.trainer.train()
  File "/home/bhavyajeet.singh/anaconda3/envs/xalign/lib/python3.7/site-packages/pytorch_lightning/trainer/trainer.py", line 467, in train
    self.run_sanity_check(self.get_model())
  File "/home/bhavyajeet.singh/anaconda3/envs/xalign/lib/python3.7/site-packages/pytorch_lightning/trainer/trainer.py", line 649, in run_sanity_check
    self.reset_val_dataloader(ref_model)
  File "/home/bhavyajeet.singh/anaconda3/envs/xalign/lib/python3.7/site-packages/pytorch_lightning/trainer/data_loading.py", line 318, in reset_val_dataloader
    self.num_val_batches, self.val_dataloaders = self._reset_eval_dataloader(model, 'val')
  File "/home/bhavyajeet.singh/anaconda3/envs/xalign/lib/python3.7/site-packages/pytorch_lightning/trainer/data_loading.py", line 238, in _reset_eval_dataloader
    dataloaders = self.request_dataloader(getattr(model, loader_name))
  File "/home/bhavyajeet.singh/anaconda3/envs/xalign/lib/python3.7/site-packages/pytorch_lightning/trainer/data_loading.py", line 341, in request_dataloader
    dataloader = dataloader_fx()
  File "/home/bhavyajeet.singh/XAlign/src/data-to-text-generator/mT5-baseline/main.py", line 291, in val_dataloader
    self.config_args.logger)
  File "/home/bhavyajeet.singh/XAlign/src/data-to-text-generator/mT5-baseline/main.py", line 279, in _intiate_dataset_merging
    merge_dataset_across_languages(dataset_dir, languages, dataset_type, os.path.join(final_dir_path, "%s.jsonl" % dataset_type))
  File "/home/bhavyajeet.singh/XAlign/src/data-to-text-generator/mT5-baseline/utils.py", line 90, in merge_dataset_across_languages
    final_res.extend(load_jsonl(file_path))
  File "/home/bhavyajeet.singh/XAlign/src/data-to-text-generator/mT5-baseline/utils.py", line 64, in load_jsonl
    with open(file_path, encoding='utf-8') as dfile:
FileNotFoundError: [Errno 2] No such file or directory: '/tmp/XAlign/datasets/en/val.jsonl'