2023-02-08 02:54:14,376 INFO    MainThread:8952 [internal.py:wandb_internal():89] W&B internal server running at pid: 8952, started at: 2023-02-08 02:54:14.375486
2023-02-08 02:54:14,380 INFO    WriterThread:8952 [datastore.py:open_for_write():77] open: /home/bhavyajeet.singh/msme/MEMS-XF2T/generation/mT5-baseline/wandb/offline-run-20230208_025412-38dctno0/run-38dctno0.wandb
2023-02-08 02:54:14,384 DEBUG   HandlerThread:8952 [handler.py:handle_request():126] handle_request: run_start
2023-02-08 02:54:19,039 DEBUG   HandlerThread:8952 [meta.py:__init__():40] meta init
2023-02-08 02:54:19,039 DEBUG   HandlerThread:8952 [meta.py:__init__():54] meta init done
2023-02-08 02:54:19,039 DEBUG   HandlerThread:8952 [meta.py:probe():211] probe
2023-02-08 02:54:19,049 DEBUG   HandlerThread:8952 [meta.py:_setup_git():201] setup git
2023-02-08 02:54:19,104 DEBUG   HandlerThread:8952 [meta.py:_setup_git():208] setup git done
2023-02-08 02:54:19,105 DEBUG   HandlerThread:8952 [meta.py:_save_pip():58] save pip
2023-02-08 02:54:19,107 DEBUG   HandlerThread:8952 [meta.py:_save_pip():72] save pip done
2023-02-08 02:54:19,107 DEBUG   HandlerThread:8952 [meta.py:_save_conda():79] save conda
2023-02-08 02:54:23,085 WARNING MainThread:8952 [internal.py:wandb_internal():145] Internal process interrupt: 1
2023-02-08 02:54:23,195 DEBUG   HandlerThread:8952 [meta.py:_save_conda():87] save conda done
2023-02-08 02:54:23,195 DEBUG   HandlerThread:8952 [meta.py:probe():249] probe done
2023-02-08 02:54:23,207 WARNING MainThread:8952 [internal.py:wandb_internal():145] Internal process interrupt: 2
2023-02-08 02:54:23,207 ERROR   MainThread:8952 [internal.py:wandb_internal():148] Internal process interrupted.
2023-02-08 02:54:23,418 INFO    SenderThread:8952 [sender.py:finish():986] shutting down sender
2023-02-08 02:54:24,207 INFO    WriterThread:8952 [datastore.py:close():281] close: /home/bhavyajeet.singh/msme/MEMS-XF2T/generation/mT5-baseline/wandb/offline-run-20230208_025412-38dctno0/run-38dctno0.wandb
2023-02-08 02:54:24,212 INFO    MainThread:8952 [internal.py:handle_exit():76] Internal process exited
