01/22/2023 08:35:20 PM [CRITICAL] val : script unification to Devanagari is enabled.
01/22/2023 08:35:20 PM [INFO] val dataset count : 159
Validation sanity check:  50%|██████████████              | 1/2 [00:00<00:00,  6.12it/s]01/22/2023 08:35:20 PM [INFO] epoch : 0 - average_val_loss : 30.172794
01/22/2023 08:35:20 PM [CRITICAL] train : script unification to Devanagari is enabled.
01/22/2023 08:35:20 PM [INFO] train dataset count : 799
Epoch 0:   2%|▎                 | 1/60 [00:00<00:50,  1.18it/s, loss=34.733, v_num=oo5q]
  | Name  | Type                        | Params
------------------------------------------------------
0 | model | MT5ForConditionalGeneration | 300 M
/home/bhavyajeet.singh/anaconda3/envs/xalign/lib/python3.7/site-packages/pytorch_lightning/utilities/distributed.py:45: UserWarning: The dataloader, val dataloader 0, does not have many workers which may be a bottleneck. Consider increasing the value of the `num_workers` argument` (try 40 which is the number of cpus on this machine) in the `DataLoader` init to improve performance.
  warnings.warn(*args, **kwargs)
/home/bhavyajeet.singh/anaconda3/envs/xalign/lib/python3.7/site-packages/pytorch_lightning/utilities/distributed.py:45: UserWarning: The dataloader, train dataloader, does not have many workers which may be a bottleneck. Consider increasing the value of the `num_workers` argument` (try 40 which is the number of cpus on this machine) in the `DataLoader` init to improve performance.













Epoch 0:  63%|███████████▍      | 38/60 [00:26<00:15,  1.41it/s, loss=7.252, v_num=oo5q]
Exception in thread Thread-4:
Traceback (most recent call last):
  File "/home/bhavyajeet.singh/anaconda3/envs/xalign/lib/python3.7/threading.py", line 926, in _bootstrap_inner
    self.run()
  File "/home/bhavyajeet.singh/anaconda3/envs/xalign/lib/python3.7/threading.py", line 870, in run
    self._target(*self._args, **self._kwargs)
  File "/home/bhavyajeet.singh/anaconda3/envs/xalign/lib/python3.7/site-packages/wandb/sdk/wandb_run.py", line 215, in check_status
    status_response = self._interface.communicate_stop_status()
  File "/home/bhavyajeet.singh/anaconda3/envs/xalign/lib/python3.7/site-packages/wandb/sdk/interface/interface.py", line 737, in communicate_stop_status
    resp = self._communicate(req, timeout=timeout, local=True)
  File "/home/bhavyajeet.singh/anaconda3/envs/xalign/lib/python3.7/site-packages/wandb/sdk/interface/interface.py", line 539, in _communicate
    return self._communicate_async(rec, local=local).get(timeout=timeout)
  File "/home/bhavyajeet.singh/anaconda3/envs/xalign/lib/python3.7/site-packages/wandb/sdk/interface/interface.py", line 544, in _communicate_async
    raise Exception("The wandb backend process has shutdown")
